Workbook

Sheet Assumptions
A1: The Cake & Crumb Co. UK – Financial Assumptions
A3: Venture Profile
A4: Item | B4: Value
A5: Business Name | B5: The Cake & Crumb Co. UK
A6: Sector | B6: Online bakery, celebration cakes and local delivery
A7: Currency | B7: GBP (£)
A9: Pricing & Sales Volume
A10: Item | B10: Value
A11: Average Price per Order (£) | B11: 45 | C11: Planning blended order value across celebration cakes, cupcakes and bakery boxes. | D11: Planning price assumption used consistently to derive revenue and unit economics.
A12: Average Orders per Month (Year 1) | B12: 300 | C12: £45 average order × 300 orders/month × 12 = £162,000 Year-1 revenue. | D12: Report forecast implies £150,000 Year-1 revenue; £50/order × 250 orders/month × 12 = £150,000.
A13: Year 2 Revenue Growth (%) | B13: 0.25 | C13: Base-case revenue growth assumption applied consistently to the forecast. | D13: Report states 25% annual customer growth; under stable average order value, revenue is modelled to grow 25%.
A14: Year 3 Revenue Growth (%) | B14: 0.25 | C14: Base-case revenue growth assumption; maintains forecast consistency. | D14: Same logic as Year 2: stable price/order economics means revenue follows the stated 25% growth assumption.
A16: Cost of Goods
A17: Item | B17: Value
A18: COGS as % of Revenue | B18: 0.4 | C18: Planning COGS assumption covering ingredients and direct production inputs; stress-tested in scenarios. | D18: Planning gross-margin assumption; 45% COGS is stress-tested in scenario analysis.
A20: Operating Expenses (monthly base in Year 1)
A21: Item | B21: Value
A22: Rent | B22: 2000 | C22: Planning rent assumption for a small bakery production/retail unit.
A23: Utilities | B23: 400 | C23: Planning utilities assumption reflecting ovens, refrigeration and premises use.
A24: Salaries and Wages | B24: 4500 | C24: Planning staffing assumption for production, fulfilment and customer service.
A25: Marketing | B25: 1000 | C25: Planning customer-acquisition budget.
A26: Insurance | B26: 200 | C26: Planning business insurance allowance.
A27: Other Opex | B27: 200 | C27: Planning miscellaneous operating costs.
A28: Opex Growth Y2 (%) | B28: 0.05 | C28: Base-case operating-cost growth; stress-tested at 4%–8%. | D28: Planning cost-inflation assumption; stress-tested at 4%–8% in scenario analysis.
A29: Opex Growth Y3 (%) | B29: 0.05 | C29: Base-case operating-cost growth; stress-tested at 4%–8%. | D29: Planning cost-inflation assumption; stress-tested at 4%–8% in scenario analysis.
A31: Funding Assumptions
A32: Item | B32: Value | C32: Description / Rationale | D32: Evidence / Basis
A33: Start-Up Loan Amount (£) | B33: 30000 | C33: Three-year start-up loan for equipment, premises and launch infrastructure. | D33: Planning assumption; lender terms to be confirmed.
A34: Annual Interest Rate (%) | B34: 0.08 | D34: Planning debt-cost assumption.
A35: Loan Term (years) | B35: 3 | D35: Aligned with the three-year forecast horizon.
A36: Repayment Starts Month | B36: 1 | D36: Planning assumption: debt service starts at launch.
A37: Personal Savings (£) | B37: 20000 | C37: Founder capital demonstrating commitment and reducing external finance reliance. | D37: Base-case funding plan.
A38: Crowdfunding/Grant (£) | B38: 0 | C38: No grant/crowdfunding assumed; treated as upside rather than required funding. | D38: Base-case decision avoids dependence on uncertain awards.
A39: Other Source of Funding (1) | B39: 40000 | C39: Angel equity funding providing growth capital without scheduled principal repayment. | D39: Equity percentage and terms to be negotiated and documented.
A40: Other Source of Funding (2) | B40: 0 | C40: No additional funding assumed in base case. | D40: Avoids overstating liquidity.
A42: Tax & KPI Assumptions
A43: Item | B43: Value
A44: Corporation Tax Rate (%) | B44: 0.19 | C44: Planning corporation-tax rate; actual liability depends on taxable profits and applicable rules.
A45: Retention Rate for LTV calc (%) | B45: 0.7 | C45: Planning customer-retention assumption for simplified LTV proxy.
A46: Average Customer Spend per Year (£) | B46: 540 | C46: Planning annual customer spend: £45 average order × 12 orders.
...

Sheet Startup Costs & Use of Funds
A1: Startup Costs and Use of Funds
A3: Category | B3: Amount (£) | C3: Notes
A4: Commercial bakery equipment | B4: 18000 | C4: Ovens, mixers, refrigeration and small production equipment.
A5: Premises fit-out | B5: 12000 | C5: Food-preparation area, electrical/plumbing works and customer-facing setup.
A6: Initial ingredients & packaging | B6: 7000 | C6: Opening ingredients, cake boards, boxes and bakery packaging.
A7: Licences, legal & food compliance | B7: 4000 | C7: Company formation, legal advice and initial compliance setup.
A8: Branding & launch marketing | B8: 7000 | C8: Brand identity, launch campaign and customer acquisition.
A9: Working Capital Buffer | B9: 20000 | C9: Ring-fenced liquidity reserve retained as cash rather than consumed at launch.
A10: Pre-launch salaries/training | B10: 4000 | C10: Limited pre-opening staffing and training.
A11: Website & e-commerce | B11: 8000 | C11: Online ordering, product catalogue and payment-enabled website.
A12: Delivery & logistics setup | B12: 8000 | C12: Local delivery equipment and initial logistics setup.
A13: POS/software/IT | B13: 2000 | C13: Till/POS, accounting and operational software setup.
A14: Other Startup Costs | B14: 0 | C14: Not required in the base case.
A15: Total Startup Costs | B15: =SUM(B4:B14) -> 90000
A17: Funding Requirement Check | B17: =B15-'Funding Mix'!B9 -> 0

Sheet CashFlow_36m
A1: The Cake & Crumb Co. UK – Monthly Cash Flow – 36 Months
A3: Month | B3: M0 (Pre-Launch) | C3: M1 | D3: M2 | E3: M3 | F3: M4 | G3: M5 | H3: M6 | I3: M7 | J3: M8 | K3: M9 | L3: M10 | M3: M11 | N3: M12 | O3: M13 | P3: M14 | Q3: M15 | R3: M16 | S3: M17 | T3: M18 | U3: M19 | V3: M20 | W3: M21 | X3: M22 | Y3: M23 | Z3: M24 | AA3: M25 | AB3: M26 | AC3: M27 | AD3: M28 | AE3: M29 | AF3: M30 | AG3: M31 | AH3: M32 | AI3: M33 | AJ3: M34 | AK3: M35 | AL3: M36
A4: Opening Cash | B4: 0 | C4: =B14 -> 20000 | D4: =C14 -> 18859.909 | E4: =D14 -> 17719.818 | F4: =E14 -> 16579.727 | G4: =F14 -> 15439.636 | H4: =G14 -> 14299.545 | I4: =H14 -> 13159.454 | J4: =I14 -> 12019.363 | ... AL4: =AK14 -> 36962.516
A5: Funding Inflow | B5: ='Funding Mix'!B9 -> 90000 | C5: 0 | D5: 0 | E5: 0 | F5: 0 | G5: 0 | H5: 0 | I5: 0 | J5: 0 | K5: 0 | L5: 0 | M5: 0 | N5: 0 | O5: 0 | P5: 0 | Q5: 0 | R5: 0 | S5: 0 | T5: 0 | U5: 0 | V5: 0 | W5: 0 | X5: 0 | Y5: 0 | Z5: 0 | AA5: 0 | AB5: 0 | AC5: 0 | AD5: 0 | AE5: 0 | AF5: 0 | AG5: 0 | AH5: 0 | AI5: 0 | AJ5: 0 | AK5: 0 | AL5: 0
A6: Startup Cash Deployed (excl. reserve) | B6: ='Startup Costs & Use of Funds'!B15-'Startup Costs & Use of Funds'!B9 -> 70000 | C6: 0 | D6: 0 | E6: 0 | F6: 0 | G6: 0 | H6: 0 | I6: 0 | J6: 0 | K6: 0 | L6: 0 | M6: 0 | N6: 0 | O6: 0 | P6: 0 | Q6: 0 | R6: 0 | S6: 0 | T6: 0 | U6: 0 | V6: 0 | W6: 0 | X6: 0 | Y6: 0 | Z6: 0 | AA6: 0 | AB6: 0 | AC6: 0 | AD6: 0 | AE6: 0 | AF6: 0 | AG6: 0 | AH6: 0 | AI6: 0 | AJ6: 0 | AK6: 0 | AL6: 0
A7: Revenue | B7: 0 | C7: =Assumptions!B11*Assumptions!B12*1 -> 13500 | D7: =Assumptions!B11*Assumptions!B12*1 -> 13500 | E7: =Assumptions!B11*Assumptions!B12*1 -> 13500 | F7: =Assumptions!B11*Assumptions!B12*1 -> 13500 | G7: =Assumptions!B11*Assumptions!B12*1 -> 13500 | H7: =Assumptions!B11*Assumptions!B12*1 -> 13500 | I7: =Assumptions!B11*Assumptions!B12*1 -> 13500 | J7: =Assumptions!B11*Assumptions!B12*1 -> 13500 | K7: =Assumptions!B11*Assumptions!B12*1 -> 13500 | L7: =Assumptions!B11*Assumptions!B12*1 -> 13500 | M7: =Assumptions!B11*Assumptions!B12*1 -> 13500 | N7: =Assumptions!B11*Assumptions!B12*1 -> 13500 | O7: =Assumptions!B11*Assumptions!B12*(1+Assumptions!B13) -> 16875 | P7: =Assumptions!B11*Assumptions!B12*(1+Assumptions!B13) -> 16875 | Q7: =Assumptions!B11*Assumptions!B12*(1+Assumptions!B13) -> 16875 | R7: =Assumptions!B11*Assumptions!B12*(1+Assumptions!B13) -> 16875 | S7: =Assumptions!B11*Assumptions!B12*(1+Assumptions!B13) -> 16875 | T7: =Assumptions!B11*Assumptions!B12*(1+Assumptions!B13) -> 16875 | U7: =Assumptions!B11*Assumptions!B12*(1+Assumptions!B13) -> 16875 | V7: =Assumptions!B11*Assumptions!B12*(1+Assumptions!B13) -> 16875 | W7: =Assumptions!B11*Assumptions!B12*(1+Assumptions!B13) -> 16875 | X7: =Assumptions!B11*Assumptions!B12*(1+Assumptions!B13) -> 16875 | Y7: =Assumptions!B11*Assumptions!B12*(1+Assumptions!B13) -> 16875 | Z7: =Assumptions!B11*Assumptions!B12*(1+Assumptions!B13) -> 16875 | AA7: =Assumptions!B11*Assumptions!B12*(1+Assumptions!B13)*(1+Assumptions!B14) -> 21093.75 | AB7: =Assumptions!B11*Assumptions!B12*(1+Assumptions!B13)*(1+Assumptions!B14) -> 21093.75 | AC7: =Assumptions!B11*Assumptions!B12*(1+Assumptions!B13)*(1+Assumptions!B14) -> 21093.75 | AD7: =Assumptions!B11*Assumptions!B12*(1+Assumptions!B13)*(1+Assumptions!B14) -> 21093.75 | AE7: =Assumptions!B11*Assumptions!B12*(1+Assumptions!B13)*(1+Assumptions!B14) -> 21093.75 | AF7: =Assumptions!B11*Assumptions!B12*(1+Assumptions!B13)*(1+Assumptions!B14) -> 21093.75 | AG7: =Assumptions!B11*Assumptions!B12*(1+Assumptions!B13)*(1+Assumptions!B14) -> 21093.75 | AH7: =Assumptions!B11*Assumptions!B12*(1+Assumptions!B13)*(1+Assumptions!B14) -> 21093.75 | AI7: =Assumptions!B11*Assumptions!B12*(1+Assumptions!B13)*(1+Assumptions!B14) -> 21093.75 | AJ7: =Assumptions!B11*Assumptions!B12*(1+Assumptions!B13)*(1+Assumptions!B14) -> 21093.75 | AK7: =Assumptions!B11*Assumptions!B12*(1+Assumptions!B13)*(1+Assumptions!B14) -> 21093.75 | AL7: =Assumptions!B11*Assumptions!B12*(1+Assumptions!B13)*(1+Assumptions!B14) -> 21093.75
A8: COGS | B8: 0 | C8: =C7*Assumptions!B18 -> 5400 | D8: =D7*Assumptions!B18 -> 5400 | E8: =E7*Assumptions!B18 -> 5400 | F8: =F7*Assumptions!B18 -> 5400 | G8: =G7*Assumptions!B18 -> 5400 | H8: =H7*Assumptions!B18 -> 5400 | I8: =I7*Assumptions!B18 -> 5400 | J8: =J7*Assumptions!B18 -> 5400 | K8: =K7*Assumptions!B18 -> 5400 | L8: =L7*Assumptions!B18 -> 5400 | M8: =M7*Assumptions!B18 -> 5400 | N8: =N7*Assumptions!B18 -> 5400 | O8: =O7*Assumptions!B18 -> 6750 | P8: =P7*Assumptions!B18 -> 6750 | Q8: =Q7*Assumptions!B18 -> 6750 | R8: =R7*Assumptions!B18 -> 6750 | S8: =S7*Assumptions!B18 -> 6750 | T8: =T7*Assumptions!B18 -> 6750 | U8: =U7*Assumptions!B18 -> 6750 | V8: =V7*Assumptions!B18 -> 6750 | W8: =W7*Assumptions!B18 -> 6750 | X8: =X7*Assumptions!B18 -> 6750 | Y8: =Y7*Assumptions!B18 -> 6750 | Z8: =Z7*Assumptions!B18 -> 6750 | AA8: =AA7*Assumptions!B18 -> 8437.5 | AB8: =AB7*Assumptions!B18 -> 8437.5 | AC8: =AC7*Assumptions!B18 -> 8437.5 | AD8: =AD7*Assumptions!B18 -> 8437.5 | AE8: =AE7*Assumptions!B18 -> 8437.5 | AF8: =AF7*Assumptions!B18 -> 8437.5 | AG8: =AG7*Assumptions!B18 -> 8437.5 | AH8: =AH7*Assumptions!B18 -> 8437.5 | AI8: =AI7*Assumptions!B18 -> 8437.5 | AJ8: =AJ7*Assumptions!B18 -> 8437.5 | AK8: =AK7*Assumptions!B18 -> 8437.5 | AL8: =AL7*Assumptions!B18 -> 8437.5
A9: Operating Expenses | B9: 0 | C9: =SUM(Assumptions!B22:B27)*1 -> 8300 | D9: =SUM(Assumptions!B22:B27)*1 -> 8300 | E9: =SUM(Assumptions!B22:B27)*1 -> 8300 | F9: =SUM(Assumptions!B22:B27)*1 -> 8300 | G9: =SUM(Assumptions!B22:B27)*1 -> 8300 | H9: =SUM(Assumptions!B22:B27)*1 -> 8300 | I9: =SUM(Assumptions!B22:B27)*1 -> 8300 | J9: =SUM(Assumptions!B22:B27)*1 -> 8300 | K9: =SUM(Assumptions!B22:B27)*1 -> 8300 | L9: =SUM(Assumptions!B22:B27)*1 -> 8300 | M9: =SUM(Assumptions!B22:B27)*1 -> 8300 | N9: =SUM(Assumptions!B22:B27)*1 -> 8300 | O9: =SUM(Assumptions!B22:B27)*(1+Assumptions!B28) -> 8715 | P9: =SUM(Assumptions!B22:B27)*(1+Assumptions!B28) -> 8715 | Q9: =SUM(Assumptions!B22:B27)*(1+Assumptions!B28) -> 8715 | R9: =SUM(Assumptions!B22:B27)*(1+Assumptions!B28) -> 8715 | S9: =SUM(Assumptions!B22:B27)*(1+Assumptions!B28) -> 8715 | T9: =SUM(Assumptions!B22:B27)*(1+Assumptions!B28) -> 8715 | U9: =SUM(Assumptions!B22:B27)*(1+Assumptions!B28) -> 8715 | V9: =SUM(Assumptions!B22:B27)*(1+Assumptions!B28) -> 8715 | W9: =SUM(Assumptions!B22:B27)*(1+Assumptions!B28) -> 8715 | X9: =SUM(Assumptions!B22:B27)*(1+Assumptions!B28) -> 8715 | Y9: =SUM(Assumptions!B22:B27)*(1+Assumptions!B28) -> 8715 | Z9: =SUM(Assumptions!B22:B27)*(1+Assumptions!B28) -> 8715 | AA9: =SUM(Assumptions!B22:B27)*(1+Assumptions!B28)*(1+Assumptions!B29) -> 9150.75 | AB9: =SUM(Assumptions!B22:B27)*(1+Assumptions!B28)*(1+Assumptions!B29) -> 9150.75 | AC9: =SUM(Assumptions!B22:B27)*(1+Assumptions!B28)*(1+Assumptions!B29) -> 9150.75 | AD9: =SUM(Assumptions!B22:B27)*(1+Assumptions!B28)*(1+Assumptions!B29) -> 9150.75 | AE9: =SUM(Assumptions!B22:B27)*(1+Assumptions!B28)*(1+Assumptions!B29) -> 9150.75 | AF9: =SUM(Assumptions!B22:B27)*(1+Assumptions!B28)*(1+Assumptions!B29) -> 9150.75 | AG9: =SUM(Assumptions!B22:B27)*(1+Assumptions!B28)*(1+Assumptions!B29) -> 9150.75 | AH9: =SUM(Assumptions!B22:B27)*(1+Assumptions!B28)*(1+Assumptions!B29) -> 9150.75 | AI9: =SUM(Assumptions!B22:B27)*(1+Assumptions!B28)*(1+Assumptions!B29) -> 9150.75 | AJ9: =SUM(Assumptions!B22:B27)*(1+Assumptions!B28)*(1+Assumptions!B29) -> 9150.75 | AK9: =SUM(Assumptions!B22:B27)*(1+Assumptions!B28)*(1+Assumptions!B29) -> 9150.75 | AL9: =SUM(Assumptions!B22:B27)*(1+Assumptions!B28)*(1+Assumptions!B29) -> 9150.75
A10: Loan Payment (PMT) | B10: 0 | C10: =IF(1<Assumptions!B36,0,-PMT(Assumptions!B34/12,Assumptions!B35*12,Assumptions!B33)) -> 940.09096 | D10: =IF(2<Assumptions!B36,0,-PMT(Assumptions!B34/12,Assumptions!B35*12,Assumptions!B33)) -> 940.09096 | E10: =IF(3<Assumptions!B36,0,-PMT(Assumptions!B34/12,Assumptions!B35*12,Assumptions!B33)) -> 940.09096 | F10: =IF(4<Assumptions!B36,0,-PMT(Assumptions!B34/12,Assumptions!B35*12,Assumptions!B33)) -> 940.09096 | G10: =IF(5<Assumptions!B36,0,-PMT(Assumptions!B34/12,Assumptions!B35*12,Assumptions!B33)) -> 940.09096 | H10: =IF(6<Assumptions!B36,0,-PMT(Assumptions!B34/12,Assumptions!B35*12,Assumptions!B33)) -> 940.09096 | I10: =IF(7<Assumptions!B36,0,-PMT(Assumptions!B34/12,Assumptions!B35*12,Assumptions!B33)) -> 940.09096 | J10: =IF(8<Assumptions!B36,0,-PMT(Assumptions!B34/12,Assumptions!B35*12,Assumptions!B33)) -> 940.09096 | K10: =IF(9<Assumptions!B36,0,-PMT(Assumptions!B34/12,Assumptions!B35*12,Assumptions!B33)) -> 940.09096 | L10: =IF(10<Assumptions!B36,0,-PMT(Assumptions!B34/12,Assumptions!B35*12,Assumptions!B33)) -> 940.09096 | M10: =IF(11<Assumptions!B36,0,-PMT(Assumptions!B34/12,Assumptions!B35*12,Assumptions!B33)) -> 940.09096 | N10: =IF(12<Assumptions!B36,0,-PMT(Assumptions!B34/12,Assumptions!B35*12,Assumptions!B33)) -> 940.09096 | O10: =IF(13<Assumptions!B36,0,-PMT(Assumptions!B34/12,Assumptions!B35*12,Assumptions!B33)) -> 940.09096 | P10: =IF(14<Assumptions!B36,0,-PMT(Assumptions!B34/12,Assumptions!B35*12,Assumptions!B33)) -> 940.09096 | Q10: =IF(15<Assumptions!B36,0,-PMT(Assumptions!B34/12,Assumptions!B35*12,Assumptions!B33)) -> 940.09096 | R10: =IF(16<Assumptions!B36,0,-PMT(Assumptions!B34/12,Assumptions!B35*12,Assumptions!B33)) -> 940.09096 | S10: =IF(17<Assumptions!B36,0,-PMT(Assumptions!B34/12,Assumptions!B35*12,Assumptions!B33)) -> 940.09096 | T10: =IF(18<Assumptions!B36,0,-PMT(Assumptions!B34/12,Assumptions!B35*12,Assumptions!B33)) -> 940.09096 | U10: =IF(19<Assumptions!B36,0,-PMT(Assumptions!B34/12,Assumptions!B35*12,Assumptions!B33)) -> 940.09096 | V10: =IF(20<Assumptions!B36,0,-PMT(Assumptions!B34/12,Assumptions!B35*12,Assumptions!B33)) -> 940.09096 | W10: =IF(21<Assumptions!B36,0,-PMT(Assumptions!B34/12,Assumptions!B35*12,Assumptions!B33)) -> 940.09096 | X10: =IF(22<Assumptions!B36,0,-PMT(Assumptions!B34/12,Assumptions!B35*12,Assumptions!B33)) -> 940.09096 | Y10: =IF(23<Assumptions!B36,0,-PMT(Assumptions!B34/12,Assumptions!B35*12,Assumptions!B33)) -> 940.09096 | Z10: =IF(24<Assumptions!B36,0,-PMT(Assumptions!B34/12,Assumptions!B35*12,Assumptions!B33)) -> 940.09096 | AA10: =IF(25<Assumptions!B36,0,-PMT(Assumptions!B34/12,Assumptions!B35*12,Assumptions!B33)) -> 940.09096 | AB10: =IF(26<Assumptions!B36,0,-PMT(Assumptions!B34/12,Assumptions!B35*12,Assumptions!B33)) -> 940.09096 | AC10: =IF(27<Assumptions!B36,0,-PMT(Assumptions!B34/12,Assumptions!B35*12,Assumptions!B33)) -> 940.09096 | AD10: =IF(28<Assumptions!B36,0,-PMT(Assumptions!B34/12,Assumptions!B35*12,Assumptions!B33)) -> 940.09096 | AE10: =IF(29<Assumptions!B36,0,-PMT(Assumptions!B34/12,Assumptions!B35*12,Assumptions!B33)) -> 940.09096 | AF10: =IF(30<Assumptions!B36,0,-PMT(Assumptions!B34/12,Assumptions!B35*12,Assumptions!B33)) -> 940.09096 | AG10: =IF(31<Assumptions!B36,0,-PMT(Assumptions!B34/12,Assumptions!B35*12,Assumptions!B33)) -> 940.09096 | AH10: =IF(32<Assumptions!B36,0,-PMT(Assumptions!B34/12,Assumptions!B35*12,Assumptions!B33)) -> 940.09096 | AI10: =IF(33<Assumptions!B36,0,-PMT(Assumptions!B34/12,Assumptions!B35*12,Assumptions!B33)) -> 940.09096 | AJ10: =IF(34<Assumptions!B36,0,-PMT(Assumptions!B34/12,Assumptions!B35*12,Assumptions!B33)) -> 940.09096 | AK10: =IF(35<Assumptions!B36,0,-PMT(Assumptions!B34/12,Assumptions!B35*12,Assumptions!B33)) -> 940.09096 | AL10: =IF(36<Assumptions!B36,0,-PMT(Assumptions!B34/12,Assumptions!B35*12,Assumptions!B33)) -> 940.09096
A11: Interest Component (for P&L) | B11: 0 | C11: =IF(1<Assumptions!B36,0,-IPMT(Assumptions!B34/12,1-Assumptions!B36+1,Assumptions!B35*12,Assumptions!B33)) -> 200 | D11: =IF(2<Assumptions!B36,0,-IPMT(Assumptions!B34/12,2-Assumptions!B36+1,Assumptions!B35*12,Assumptions!B33)) -> 195.06606 | E11: =IF(3<Assumptions!B36,0,-IPMT(Assumptions!B34/12,3-Assumptions!B36+1,Assumptions!B35*12,Assumptions!B33)) -> 190.09923 | F11: =IF(4<Assumptions!B36,0,-IPMT(Assumptions!B34/12,4-Assumptions!B36+1,Assumptions!B35*12,Assumptions!B33)) -> 185.09928 | G11: =IF(5<Assumptions!B36,0,-IPMT(Assumptions!B34/12,5-Assumptions!B36+1,Assumptions!B35*12,Assumptions!B33)) -> 180.066 | H11: =IF(6<Assumptions!B36,0,-IPMT(Assumptions!B34/12,6-Assumptions!B36+1,Assumptions!B35*12,Assumptions!B33)) -> 174.99917 | I11: =IF(7<Assumptions!B36,0,-IPMT(Assumptions!B34/12,7-Assumptions!B36+1,Assumptions!B35*12,Assumptions!B33)) -> 169.89856 | J11: =IF(8<Assumptions!B36,0,-IPMT(Assumptions!B34/12,8-Assumptions!B36+1,Assumptions!B35*12,Assumptions!B33)) -> 164.76394 | K11: =IF(9<Assumptions!B36,0,-IPMT(Assumptions!B34/12,9-Assumptions!B36+1,Assumptions!B35*12,Assumptions!B33)) -> 159.5951 | L11: =IF(10<Assumptions!B36,0,-IPMT(Assumptions!B34/12,10-Assumptions!B36+1,Assumptions!B35*12,Assumptions!B33)) -> 154.39179 | M11: =IF(11<Assumptions!B36,0,-IPMT(Assumptions!B34/12,11-Assumptions!B36+1,Assumptions!B35*12,Assumptions!B33)) -> 149.1538 | N11: =IF(12<Assumptions!B36,0,-IPMT(Assumptions!B34/12,12-Assumptions!B36+1,Assumptions!B35*12,Assumptions!B33)) -> 143.88088 | O11: =IF(13<Assumptions!B36,0,-IPMT(Assumptions!B34/12,13-Assumptions!B36+1,Assumptions!B35*12,Assumptions!B33)) -> 138.57282 | P11: =IF(14<Assumptions!B36,0,-IPMT(Assumptions!B34/12,14-Assumptions!B36+1,Assumptions!B35*12,Assumptions!B33)) -> 133.22936 | Q11: =IF(15<Assumptions!B36,0,-IPMT(Assumptions!B34/12,15-Assumptions!B36+1,Assumptions!B35*12,Assumptions!B33)) -> 127.85028 | R11: =IF(16<Assumptions!B36,0,-IPMT(Assumptions!B34/12,16-Assumptions!B36+1,Assumptions!B35*12,Assumptions!B33)) -> 122.43535 | S11: =IF(17<Assumptions!B36,0,-IPMT(Assumptions!B34/12,17-Assumptions!B36+1,Assumptions!B35*12,Assumptions!B33)) -> 116.98431 | T11: =IF(18<Assumptions!B36,0,-IPMT(Assumptions!B34/12,18-Assumptions!B36+1,Assumptions!B35*12,Assumptions!B33)) -> 111.49693 | U11: =IF(19<Assumptions!B36,0,-IPMT(Assumptions!B34/12,19-Assumptions!B36+1,Assumptions!B35*12,Assumptions!B33)) -> 105.97297 | V11: =IF(20<Assumptions!B36,0,-IPMT(Assumptions!B34/12,20-Assumptions!B36+1,Assumptions!B35*12,Assumptions!B33)) -> 100.41218 | W11: =IF(21<Assumptions!B36,0,-IPMT(Assumptions!B34/12,21-Assumptions!B36+1,Assumptions!B35*12,Assumptions!B33)) -> 94.814325 | X11: =IF(22<Assumptions!B36,0,-IPMT(Assumptions!B34/12,22-Assumptions!B36+1,Assumptions!B35*12,Assumptions!B33)) -> 89.179147 | Y11: =IF(23<Assumptions!B36,0,-IPMT(Assumptions!B34/12,23-Assumptions!B36+1,Assumptions!B35*12,Assumptions!B33)) -> 83.506402 | Z11: =IF(24<Assumptions!B36,0,-IPMT(Assumptions!B34/12,24-Assumptions!B36+1,Assumptions!B35*12,Assumptions!B33)) -> 77.795838 | AA11: =IF(25<Assumptions!B36,0,-IPMT(Assumptions!B34/12,25-Assumptions!B36+1,Assumptions!B35*12,Assumptions!B33)) -> 72.047204 | AB11: =IF(26<Assumptions!B36,0,-IPMT(Assumptions!B34/12,26-Assumptions!B36+1,Assumptions!B35*12,Assumptions!B33)) -> 66.260246 | AC11: =IF(27<Assumptions!B36,0,-IPMT(Assumptions!B34/12,27-Assumptions!B36+1,Assumptions!B35*12,Assumptions!B33)) -> 60.434707 | AD11: =IF(28<Assumptions!B36,0,-IPMT(Assumptions!B34/12,28-Assumptions!B36+1,Assumptions!B35*12,Assumptions!B33)) -> 54.570332 | AE11: =IF(29<Assumptions!B36,0,-IPMT(Assumptions!B34/12,29-Assumptions!B36+1,Assumptions!B35*12,Assumptions!B33)) -> 48.666862 | AF11: =IF(30<Assumptions!B36,0,-IPMT(Assumptions!B34/12,30-Assumptions!B36+1,Assumptions!B35*12,Assumptions!B33)) -> 42.724034 | AG11: =IF(31<Assumptions!B36,0,-IPMT(Assumptions!B34/12,31-Assumptions!B36+1,Assumptions!B35*12,Assumptions!B33)) -> 36.741588 | AH11: =IF(32<Assumptions!B36,0,-IPMT(Assumptions!B34/12,32-Assumptions!B36+1,Assumptions!B35*12,Assumptions!B33)) -> 30.719259 | AI11: =IF(33<Assumptions!B36,0,-IPMT(Assumptions!B34/12,33-Assumptions!B36+1,Assumptions!B35*12,Assumptions!B33)) -> 24.656781 | AJ11: =IF(34<Assumptions!B36,0,-IPMT(Assumptions!B34/12,34-Assumptions!B36+1,Assumptions!B35*12,Assumptions!B33)) -> 18.553886 | AK11: =IF(35<Assumptions!B36,0,-IPMT(Assumptions!B34/12,35-Assumptions!B36+1,Assumptions!B35*12,Assumptions!B33)) -> 12.410306 | AL11: =IF(36<Assumptions!B36,0,-IPMT(Assumptions!B34/12,36-Assumptions!B36+1,Assumptions!B35*12,Assumptions!B33)) -> 6.225768
A12: Tax Cash Payment | B12: 0 | C12: =0 -> 0 | D12: =0 -> 0 | E12: =0 -> 0 | F12: =0 -> 0 | G12: =0 -> 0 | H12: =0 -> 0 | I12: =0 -> 0 | J12: =0 -> 0 | ... M12: =0 -> 0 | N12: ='P&L_3yr'!B11 -> 0 | O12: =0 -> 0 | P12: =0 -> 0 | Q12: =0 -> 0 | R12: =0 -> 0 | S12: =0 -> 0 | T12: =0 -> 0 | U12: =0 -> 0 | V12: =0 -> 0 | ... Y12: =0 -> 0 | Z12: ='P&L_3yr'!C11 -> 3214.8 | AA12: =0 -> 0 | AB12: =0 -> 0 | AC12: =0 -> 0 | AD12: =0 -> 0 | AE12: =0 -> 0 | AF12: =0 -> 0 | AG12: =0 -> 0 | AH12: =0 -> 0 | ... AK12: =0 -> 0 | AL12: ='P&L_3yr'!D11 -> 7992.54
A13: Net Cash Flow | B13: =B5-B6+B7-B8-B9-B10-B12 -> 20000 | C13: =C5-C6+C7-C8-C9-C10-C12 -> -1140.091 | D13: =D5-D6+D7-D8-D9-D10-D12 -> -1140.091 | E13: =E5-E6+E7-E8-E9-E10-E12 -> -1140.091 | F13: =F5-F6+F7-F8-F9-F10-F12 -> -1140.091 | G13: =G5-G6+G7-G8-G9-G10-G12 -> -1140.091 | H13: =H5-H6+H7-H8-H9-H10-H12 -> -1140.091 | I13: =I5-I6+I7-I8-I9-I10-I12 -> -1140.091 | ... AL13: =AL5-AL6+AL7-AL8-AL9-AL10-AL12 -> -5427.131
A14: Closing Cash | B14: =B4+B13 -> 20000 | C14: =C4+C13 -> 18859.909 | D14: =D4+D13 -> 17719.818 | E14: =E4+E13 -> 16579.727 | F14: =F4+F13 -> 15439.636 | G14: =G4+G13 -> 14299.545 | H14: =H4+H13 -> 13159.454 | I14: =I4+I13 -> 12019.363 | ... AL14: =AL4+AL13 -> 31535.385
A42: Interest Totals by Year (for P&L link)
A43: Interest Totals by Year (for P&L link) | C43: =IFERROR(SUM(C11:N11),0) -> 2067.0138 | D43: Year 2 Interest | E43: =IFERROR(SUM(O11:Z11),0) -> 1302.2499 | F43: Year 3 Interest | G43: =IFERROR(SUM(AA11:AL11),0) -> 474.01097
A45: Year 1 Interest | B45: =SUM(C11:N11) -> 2067.0138 | C45: =SUM(O11:Z11) -> 1302.2499 | D45: =SUM(AA11:AL11) -> 474.01097
A46: Year 2 Interest
A47: Year 3 Interest

Sheet Funding Mix
A1: The Cake & Crumb Co. UK – Funding Sources Summary
A3: Source of Finance | B3: Amount (£) | C3: % of Total | D3: Description / Rationale
A4: =Assumptions!A37 -> Personal Savings (£) | B4: =Assumptions!B37 -> 20000 | C4: =IF(SUM($B$4:$B$8)>0,B4/SUM($B$4:$B$8),0) -> 0.22222222 | D4: =Assumptions!C37 -> Founder capital demonstrating commitment and reducing external finance reliance.
A5: =Assumptions!A33 -> Start-Up Loan Amount (£) | B5: =Assumptions!B33 -> 30000 | C5: =IF(SUM($B$4:$B$8)>0,B5/SUM($B$4:$B$8),0) -> 0.33333333 | D5: =Assumptions!C33 -> Three-year start-up loan for equipment, premises and launch infrastructure.
A6: =Assumptions!A39 -> Other Source of Funding (1) | B6: =Assumptions!B39 -> 40000 | C6: =IF(SUM($B$4:$B$8)>0,B6/SUM($B$4:$B$8),0) -> 0.44444444 | D6: =Assumptions!C39 -> Angel equity funding providing growth capital without scheduled principal repayment.
A7: =Assumptions!A38 -> Crowdfunding/Grant (£) | B7: =Assumptions!B38 -> 0 | C7: =IF(SUM($B$4:$B$8)>0,B7/SUM($B$4:$B$8),0) -> 0 | D7: =Assumptions!C38 -> No grant/crowdfunding assumed; treated as upside rather than required funding.
A8: =Assumptions!A40 -> Other Source of Funding (2) | B8: =Assumptions!B40 -> 0 | C8: =IF(SUM($B$4:$B$8)>0,B8/SUM($B$4:$B$8),0) -> 0 | D8: =Assumptions!C40 -> No additional funding assumed in base case.
A9: Total Funding | B9: =SUM(B4:B8) -> 90000
A11: Startup Costs Total (linked) | B11: ='Startup Costs & Use of Funds'!B15 -> 90000 | C11: Status | D11: =IF(B9=B11,"Balanced",IF(B9<B11,"Funding Gap","Surplus Funding")) -> Balanced
A12: Funding Surplus / (Deficit) | B12: =B9-B11 -> 0

Sheet P&L_3yr
A1: The Cake & Crumb Co. UK – Profit and Loss Summary – 3 Years
A3: Category | B3: Year 1 (£) | C3: Year 2 (£) | D3: Year 3 (£)
A4: Revenue | B4: =Assumptions!B11*Assumptions!B12*12 -> 162000 | C4: =B4*(1+Assumptions!B13) -> 202500 | D4: =C4*(1+Assumptions!B14) -> 253125
A5: COGS | B5: =B4*Assumptions!B18 -> 64800 | C5: =C4*Assumptions!B18 -> 81000 | D5: =D4*Assumptions!B18 -> 101250
A6: Gross Profit | B6: =B4-B5 -> 97200 | C6: =C4-C5 -> 121500 | D6: =D4-D5 -> 151875
A7: Operating Expenses | B7: =SUM(Assumptions!B22:B27)*12 -> 99600 | C7: =B7*(1+Assumptions!B28) -> 104580 | D7: =C7*(1+Assumptions!B29) -> 109809
A8: EBIT | B8: =B6-B7 -> -2400 | C8: =C6-C7 -> 16920 | D8: =D6-D7 -> 42066
A9: Interest Expense | B9: =CashFlow_36m!B46 -> 0 | C9: =CashFlow_36m!C46 -> 0 | D9: =CashFlow_36m!D46 -> 0
A10: Profit Before Tax | B10: =B8-B9 -> -2400 | C10: =C8-C9 -> 16920 | D10: =D8-D9 -> 42066
A11: Tax | B11: =IF(B10>0,B10*Assumptions!B44,0) -> 0 | C11: =IF(C10>0,C10*Assumptions!B44,0) -> 3214.8 | D11: =IF(D10>0,D10*Assumptions!B44,0) -> 7992.54
A12: Net Profit After Tax | B12: =B10-B11 -> -2400 | C12: =C10-C11 -> 13705.2 | D12: =D10-D11 -> 34073.46

Sheet Break-Even
B1: Break Even | Y1: Units / Orders | Z1: Revenue (£) | AA1: Total Cost (£)
B2: Break-Even Analysis | H2: Contribution | Y2: 0 | Z2: 0 | AA2: 90000
E3: Units | F3: Sales | G3: Variable Cost | H3: Contribution | I3: Fixed Cost | J3: Total Cost | K3: Net Income | Y3: 500 | Z3: 25000 | AA3: 101250
B4: Units(min) | C4: 0 | E4: 0 | F4: =E4*$C$6 -> 0 | G4: =E4*$C$7 -> 0 | H4: =F4-G4 -> 0 | I4: =$C$9 -> 99600 | J4: =G4+I4 -> 99600 | K4: =F4-J4 -> -99600 | Y4: 1000 | Z4: 50000 | AA4: 112500
B5: Units (increment) | C5: 100 | E5: =E4+$C$5 -> 100 | F5: =E5*$C$6 -> 4500 | G5: =E5*$C$7 -> 1800 | H5: =F5-G5 -> 2700 | I5: =$C$9 -> 99600 | J5: =G5+I5 -> 101400 | K5: =F5-J5 -> -96900 | Y5: 1500 | Z5: 75000 | AA5: 123750
B6: Unit Price | C6: =Assumptions!B11 -> 45 | E6: =E5+$C$5 -> 200 | F6: =E6*$C$6 -> 9000 | G6: =E6*$C$7 -> 3600 | H6: =F6-G6 -> 5400 | I6: =$C$9 -> 99600 | J6: =G6+I6 -> 103200 | K6: =F6-J6 -> -94200 | Y6: 2000 | Z6: 100000 | AA6: 135000
B7: Unit Variable Cost | C7: =Assumptions!B11*Assumptions!B18 -> 18 | E7: =E6+$C$5 -> 300 | F7: =E7*$C$6 -> 13500 | G7: =E7*$C$7 -> 5400 | H7: =F7-G7 -> 8100 | I7: =$C$9 -> 99600 | J7: =G7+I7 -> 105000 | K7: =F7-J7 -> -91500 | Y7: 2500 | Z7: 125000 | AA7: 146250
B8: Contribution Margin Per Unit | C8: =C6-C7 -> 27 | E8: =E7+$C$5 -> 400 | F8: =E8*$C$6 -> 18000 | G8: =E8*$C$7 -> 7200 | H8: =F8-G8 -> 10800 | I8: =$C$9 -> 99600 | J8: =G8+I8 -> 106800 | K8: =F8-J8 -> -88800 | Y8: 3000 | Z8: 150000 | AA8: 157500
B9: Total Fixed Cost | C9: =SUM(Assumptions!B22:B27)*12 -> 99600 | E9: =E8+$C$5 -> 500 | F9: =E9*$C$6 -> 22500 | G9: =E9*$C$7 -> 9000 | H9: =F9-G9 -> 13500 | I9: =$C$9 -> 99600 | J9: =G9+I9 -> 108600 | K9: =F9-J9 -> -86100 | Y9: 3272.73 | Z9: 163636.36 | AA9: 163636.36
E10: =E9+$C$5 -> 600 | F10: =E10*$C$6 -> 27000 | G10: =E10*$C$7 -> 10800 | H10: =F10-G10 -> 16200 | I10: =$C$9 -> 99600 | J10: =G10+I10 -> 110400 | K10: =F10-J10 -> -83400 | Y10: 3500 | Z10: 175000 | AA10: 168750
B11: Break Even (Units) | C11: =C9/C8 -> 3688.8889 | E11: =E10+$C$5 -> 700 | F11: =E11*$C$6 -> 31500 | G11: =E11*$C$7 -> 12600 | H11: =F11-G11 -> 18900 | I11: =$C$9 -> 99600 | J11: =G11+I11 -> 112200 | K11: =F11-J11 -> -80700 | Y11: 4000 | Z11: 200000 | AA11: 180000
B12: Break Even (Sales) | C12: =C11*C6 -> 166000 | E12: =E11+$C$5 -> 800 | F12: =E12*$C$6 -> 36000 | G12: =E12*$C$7 -> 14400 | H12: =F12-G12 -> 21600 | I12: =$C$9 -> 99600 | J12: =G12+I12 -> 114000 | K12: =F12-J12 -> -78000 | Y12: 4500 | Z12: 225000 | AA12: 191250
E13: =E12+$C$5 -> 900 | F13: =E13*$C$6 -> 40500 | G13: =E13*$C$7 -> 16200 | H13: =F13-G13 -> 24300 | I13: =$C$9 -> 99600 | J13: =G13+I13 -> 115800 | K13: =F13-J13 -> -75300 | Y13: 5000 | Z13: 250000 | AA13: 202500
B14: Break Even Data Label Text | E14: =E13+$C$5 -> 1000 | F14: =E14*$C$6 -> 45000 | G14: =E14*$C$7 -> 18000 | H14: =F14-G14 -> 27000 | I14: =$C$9 -> 99600 | J14: =G14+I14 -> 117600 | K14: =F14-J14 -> -72600 | Y14: 5500 | Z14: 275000 | AA14: 213750
B15: =B11&":"&TEXT(C11,"0")&CHAR(10)&B12&":"&TEXT(C12,"£#,##0") -> Break Even (Units):3689 Break Even (Sales):£1,66,000 | E15: =E14+$C$5 -> 1100 | F15: =E15*$C$6 -> 49500 | G15: =E15*$C$7 -> 19800 | H15: =F15-G15 -> 29700 | I15: =$C$9 -> 99600 | J15: =G15+I15 -> 119400 | K15: =F15-J15 -> -69900 | Y15: 6000 | Z15: 300000 | AA15: 225000
E16: =E15+$C$5 -> 1200 | F16: =E16*$C$6 -> 54000 | G16: =E16*$C$7 -> 21600 | H16: =F16-G16 -> 32400 | I16: =$C$9 -> 99600 | J16: =G16+I16 -> 121200 | K16: =F16-J16 -> -67200
E17: =E16+$C$5 -> 1300 | F17: =E17*$C$6 -> 58500 | G17: =E17*$C$7 -> 23400 | H17: =F17-G17 -> 35100 | I17: =$C$9 -> 99600 | J17: =G17+I17 -> 123000 | K17: =F17-J17 -> -64500
C18: Change the Units Increment in Cell C5 to refine the break-even chart resolution. | E18: =E17+$C$5 -> 1400 | F18: =E18*$C$6 -> 63000 | G18: =E18*$C$7 -> 25200 | H18: =F18-G18 -> 37800 | I18: =$C$9 -> 99600 | J18: =G18+I18 -> 124800 | K18: =F18-J18 -> -61800
E19: =E18+$C$5 -> 1500 | F19: =E19*$C$6 -> 67500 | G19: =E19*$C$7 -> 27000 | H19: =F19-G19 -> 40500 | I19: =$C$9 -> 99600 | J19: =G19+I19 -> 126600 | K19: =F19-J19 -> -59100
E20: =E19+$C$5 -> 1600 | F20: =E20*$C$6 -> 72000 | G20: =E20*$C$7 -> 28800 | H20: =F20-G20 -> 43200 | I20: =$C$9 -> 99600 | J20: =G20+I20 -> 128400 | K20: =F20-J20 -> -56400
E21: =E20+$C$5 -> 1700 | F21: =E21*$C$6 -> 76500 | G21: =E21*$C$7 -> 30600 | H21: =F21-G21 -> 45900 | I21: =$C$9 -> 99600 | J21: =G21+I21 -> 130200 | K21: =F21-J21 -> -53700
E22: =E21+$C$5 -> 1800 | F22: =E22*$C$6 -> 81000 | G22: =E22*$C$7 -> 32400 | H22: =F22-G22 -> 48600 | I22: =$C$9 -> 99600 | J22: =G22+I22 -> 132000 | K22: =F22-J22 -> -51000
E23: =E22+$C$5 -> 1900 | F23: =E23*$C$6 -> 85500 | G23: =E23*$C$7 -> 34200 | H23: =F23-G23 -> 51300 | I23: =$C$9 -> 99600 | J23: =G23+I23 -> 133800 | K23: =F23-J23 -> -48300
E24: =E23+$C$5 -> 2000 | F24: =E24*$C$6 -> 90000 | G24: =E24*$C$7 -> 36000 | H24: =F24-G24 -> 54000 | I24: =$C$9 -> 99600 | J24: =G24+I24 -> 135600 | K24: =F24-J24 -> -45600
E25: =E24+$C$5 -> 2100 | F25: =E25*$C$6 -> 94500 | G25: =E25*$C$7 -> 37800 | H25: =F25-G25 -> 56700 | I25: =$C$9 -> 99600 | J25: =G25+I25 -> 137400 | K25: =F25-J25 -> -42900
E26: =E25+$C$5 -> 2200 | F26: =E26*$C$6 -> 99000 | G26: =E26*$C$7 -> 39600 | H26: =F26-G26 -> 59400 | I26: =$C$9 -> 99600 | J26: =G26+I26 -> 139200 | K26: =F26-J26 -> -40200
E27: =E26+$C$5 -> 2300 | F27: =E27*$C$6 -> 103500 | G27: =E27*$C$7 -> 41400 | H27: =F27-G27 -> 62100 | I27: =$C$9 -> 99600 | J27: =G27+I27 -> 141000 | K27: =F27-J27 -> -37500
E28: =E27+$C$5 -> 2400 | F28: =E28*$C$6 -> 108000 | G28: =E28*$C$7 -> 43200 | H28: =F28-G28 -> 64800 | I28: =$C$9 -> 99600 | J28: =G28+I28 -> 142800 | K28: =F28-J28 -> -34800
E29: =E28+$C$5 -> 2500 | F29: =E29*$C$6 -> 112500 | G29: =E29*$C$7 -> 45000 | H29: =F29-G29 -> 67500 | I29: =$C$9 -> 99600 | J29: =G29+I29 -> 144600 | K29: =F29-J29 -> -32100
E30: =E29+$C$5 -> 2600 | F30: =E30*$C$6 -> 117000 | G30: =E30*$C$7 -> 46800 | H30: =F30-G30 -> 70200 | I30: =$C$9 -> 99600 | J30: =G30+I30 -> 146400 | K30: =F30-J30 -> -29400
... E54: =E53+$C$5 -> 5000 | F54: =E54*$C$6 -> 225000 | G54: =E54*$C$7 -> 90000 | H54: =F54-G54 -> 135000 | I54: =$C$9 -> 99600 | J54: =G54+I54 -> 189600 | K54: =F54-J54 -> 35400

Sheet KPIs_ByYear
A1: The Cake & Crumb Co. UK – Key Metrics and Ratios by Year
A3: Metric | B3: Year 1 | C3: Year 2 | D3: Year 3 | E3: Definition
A4: Revenue | B4: ='P&L_3yr'!B4 -> 162000 | C4: ='P&L_3yr'!C4 -> 202500 | D4: ='P&L_3yr'!D4 -> 253125 | E4: Price × orders × 12 with growth
A5: COGS | B5: ='P&L_3yr'!B5 -> 64800 | C5: ='P&L_3yr'!C5 -> 81000 | D5: ='P&L_3yr'!D5 -> 101250 | E5: COGS % of revenue
A6: Gross Profit | B6: ='P&L_3yr'!B6 -> 97200 | C6: ='P&L_3yr'!C6 -> 121500 | D6: ='P&L_3yr'!D6 -> 151875 | E6: Revenue – COGS
A7: Operating Expenses | B7: ='P&L_3yr'!B7 -> 99600 | C7: ='P&L_3yr'!C7 -> 104580 | D7: ='P&L_3yr'!D7 -> 109809 | E7: Yearly opex
A8: Interest | B8: ='P&L_3yr'!B9 -> 0 | C8: ='P&L_3yr'!C9 -> 0 | D8: ='P&L_3yr'!D9 -> 0 | E8: Annual interest expense
A9: Net Profit After Tax | B9: ='P&L_3yr'!B12 -> -2400 | C9: ='P&L_3yr'!C12 -> 13705.2 | D9: ='P&L_3yr'!D12 -> 34073.46 | E9: PBT – tax
A10: Gross Margin | B10: ='P&L_3yr'!B6/'P&L_3yr'!B4 -> 0.6 | C10: ='P&L_3yr'!C6/'P&L_3yr'!C4 -> 0.6 | D10: ='P&L_3yr'!D6/'P&L_3yr'!D4 -> 0.6 | E10: Gross Profit / Revenue
A11: Net Margin | B11: ='P&L_3yr'!B12/'P&L_3yr'!B4 -> -0.014814815 | C11: ='P&L_3yr'!C12/'P&L_3yr'!C4 -> 0.06768 | D11: ='P&L_3yr'!D12/'P&L_3yr'!D4 -> 0.1346112 | E11: NPAT / Revenue
A12: CAC | B12: =IFERROR(Assumptions!B49/Assumptions!B48,0) -> 40 | C12: =IFERROR(Assumptions!B49/Assumptions!B48,0) -> 40 | D12: =IFERROR(Assumptions!B49/Assumptions!B48,0) -> 40 | E12: Marketing spend ÷ new customers
A13: LTV | B13: =((Assumptions!B46*Assumptions!B45)-Assumptions!B47) -> 162 | C13: =((Assumptions!B46*Assumptions!B45)-Assumptions!B47) -> 162 | D13: =((Assumptions!B46*Assumptions!B45)-Assumptions!B47) -> 162 | E13: Simplified planning proxy
A14: LTV:CAC | B14: =IFERROR(B13/B12,0) -> 4.05 | C14: =IFERROR(C13/C12,0) -> 4.05 | D14: =IFERROR(D13/D12,0) -> 4.05 | E14: LTV ÷ CAC
A16: Break Even (Units) | B16: ='Break-Even'!C11 -> 3688.8889
A17: Break Even (Sales) | B17: ='Break-Even'!C12 -> 166000

Sheet Dashboard
A1: The Cake & Crumb Co. UK – Financial Dashboard
A3: Key Financial Indicators | F3: Funding & Viability
A4: Metric | B4: Year 1 | C4: Year 2 | D4: Year 3 | F4: Total Funding | G4: ='Funding Mix'!B9 -> 90000
A5: Revenue | B5: ='P&L_3yr'!B4 -> 162000 | C5: ='P&L_3yr'!C4 -> 202500 | D5: ='P&L_3yr'!D4 -> 253125 | F5: Startup Costs | G5: ='Startup Costs & Use of Funds'!B15 -> 90000
A6: Gross Profit | B6: ='P&L_3yr'!B6 -> 97200 | C6: ='P&L_3yr'!C6 -> 121500 | D6: ='P&L_3yr'!D6 -> 151875 | F6: Working Capital Reserve | G6: ='Startup Costs & Use of Funds'!B9 -> 20000
A7: EBIT | B7: ='P&L_3yr'!B8 -> -2400 | C7: ='P&L_3yr'!C8 -> 16920 | D7: ='P&L_3yr'!D8 -> 42066 | F7: Break-even Units | G7: ='Break-Even'!C11 -> 3688.8889
A8: Net Profit After Tax | B8: ='P&L_3yr'!B12 -> -2400 | C8: ='P&L_3yr'!C12 -> 13705.2 | D8: ='P&L_3yr'!D12 -> 34073.46 | F8: Break-even Sales | G8: ='Break-Even'!C12 -> 166000
A9: Gross Margin | B9: =KPIs_ByYear!B10 -> 0.6 | C9: =KPIs_ByYear!C10 -> 0.6 | D9: =KPIs_ByYear!D10 -> 0.6 | F9: LTV:CAC | G9: =KPIs_ByYear!B14 -> 4.05
A10: Net Margin | B10: =KPIs_ByYear!B11 -> -0.014814815 | C10: =KPIs_ByYear!C11 -> 0.06768 | D10: =KPIs_ByYear!D11 -> 0.1346112 | F10: Funding Status | G10: ='Funding Mix'!D11 -> Balanced
A11: Closing Cash | B11: =CashFlow_36m!N14 -> 6318.9084 | C11: =CashFlow_36m!Z14 -> 8743.0169 | D11: =CashFlow_36m!AL14 -> 31535.385
F13: Model Checks
A14: All figures are planning assumptions and model outputs; scenarios are sensitivities, not market forecasts. | F14: Funding matches startup requirement | G14: =IF(G4=G5,"PASS","CHECK") -> PASS
F15: Revenue growth matches 25% base assumption | G15: =IF(AND(ABS(C5/B5-1-Assumptions!B13)<0.0001,ABS(D5/C5-1-Assumptions!B14)<0.0001),"PASS","CHECK") -> PASS
F16: Base-case closing cash non-negative | G16: =IF(MIN(B11:D11)>=0,"PASS","CHECK") -> PASS
F17: Worst-case liquidity warning | G17: =IF('Scenario Analysis'!E14<0,"WARNING – downside funding needed","PASS") -> WARNING – downside funding needed

Sheet Scenario Analysis
A1: The Cake & Crumb Co. UK – Quantified Scenario Analysis
A2: Sensitivity testing of demand growth, COGS and operating-cost growth. Scenarios are planning sensitivities, not market forecasts.
A4: Scenario | B4: Y2 Growth | C4: Y3 Growth | D4: COGS % | E4: Opex Growth | F4: Y1 Revenue | G4: Y2 Revenue | H4: Y3 Revenue | I4: Y3 NPAT | J4: Y3 Net Margin | K4: Y3 Closing Cash | L4: Break-even Units
A5: Best | B5: 0.35 | C5: 0.35 | D5: 0.35 | E5: 0.04 | F5: =Assumptions!B11*Assumptions!B12*12 -> 162000 | G5: =F5*(1+B5) -> 218700 | H5: =G5*(1+C5) -> 295245 | I5: =((H5*(1-D5))-(SUM(Assumptions!B22:B27)*12*(1+E5)^2)-CashFlow_36m!D45)*(1-Assumptions!B44) -> 67803.382 | J5: =I5/H5 -> 0.22965125 | K5: =20000+(F5*(1-D5)-SUM(Assumptions!B22:B27)*12*1+PMT(Assumptions!B34/12,Assumptions!B35*12,Assumptions!B33)*12-IF((F5*(1-D5)-SUM(Assumptions!B22:B27)*12*1-CashFlow_36m!B45)>0,(F5*(1-D5)-SUM(Assumptions!B22:B27)*12*1-CashFlow_36m!B45)*Assumptions!B44,0))+(G5*(1-D5)-SUM(Assumptions!B22:B27)*12*(1+E5)+PMT(Assumptions!B34/12,Assumptions!B35*12,Assumptions!B33)*12-IF((G5*(1-D5)-SUM(Assumptions!B22:B27)*12*(1+E5)-CashFlow_36m!C45)>0,(G5*(1-D5)-SUM(Assumptions!B22:B27)*12*(1+E5)-CashFlow_36m!C45)*Assumptions!B44,0))+(H5*(1-D5)-SUM(Assumptions!B22:B27)*12*(1+E5)^2+PMT(Assumptions!B34/12,Assumptions!B35*12,Assumptions!B33)*12-IF((H5*(1-D5)-SUM(Assumptions!B22:B27)*12*(1+E5)^2-CashFlow_36m!D45)>0,(H5*(1-D5)-SUM(Assumptions!B22:B27)*12*(1+E5)^2-CashFlow_36m!D45)*Assumptions!B44,0)) -> 90933.788 | L5: =SUM(Assumptions!B22:B27)*12/(Assumptions!B11*(1-D5)) -> 3405.1282
A6: Base | B6: =Assumptions!B13 -> 0.25 | C6: =Assumptions!B14 -> 0.25 | D6: =Assumptions!B18 -> 0.4 | E6: =Assumptions!B28 -> 0.05 | F6: =Assumptions!B11*Assumptions!B12*12 -> 162000 | G6: =F6*(1+B6) -> 202500 | H6: =G6*(1+C6) -> 253125 | I6: =((H6*(1-D6))-(SUM(Assumptions!B22:B27)*12*(1+E6)^2)-CashFlow_36m!D45)*(1-Assumptions!B44) -> 33689.511 | J6: =I6/H6 -> 0.13309436 | K6: =20000+(F6*(1-D6)-SUM(Assumptions!B22:B27)*12*1+PMT(Assumptions!B34/12,Assumptions!B35*12,Assumptions!B33)*12-IF((F6*(1-D6)-SUM(Assumptions!B22:B27)*12*1-CashFlow_36m!B45)>0,(F6*(1-D6)-SUM(Assumptions!B22:B27)*12*1-CashFlow_36m!B45)*Assumptions!B44,0))+(G6*(1-D6)-SUM(Assumptions!B22:B27)*12*(1+E6)+PMT(Assumptions!B34/12,Assumptions!B35*12,Assumptions!B33)*12-IF((G6*(1-D6)-SUM(Assumptions!B22:B27)*12*(1+E6)-CashFlow_36m!C45)>0,(G6*(1-D6)-SUM(Assumptions!B22:B27)*12*(1+E6)-CashFlow_36m!C45)*Assumptions!B44,0))+(H6*(1-D6)-SUM(Assumptions!B22:B27)*12*(1+E6)^2+PMT(Assumptions!B34/12,Assumptions!B35*12,Assumptions!B33)*12-IF((H6*(1-D6)-SUM(Assumptions!B22:B27)*12*(1+E6)^2-CashFlow_36m!D45)>0,(H6*(1-D6)-SUM(Assumptions!B22:B27)*12*(1+E6)^2-CashFlow_36m!D45)*Assumptions!B44,0)) -> 31872.875 | L6: =SUM(Assumptions!B22:B27)*12/(Assumptions!B11*(1-D6)) -> 3688.8889
A7: Worst | B7: 0.1 | C7: 0.1 | D7: 0.45 | E7: 0.08 | F7: =Assumptions!B11*Assumptions!B12*12 -> 162000 | G7: =F7*(1+B7) -> 178200 | H7: =G7*(1+C7) -> 196020 | I7: =((H7*(1-D7))-(SUM(Assumptions!B22:B27)*12*(1+E7)^2)-CashFlow_36m!D45)*(1-Assumptions!B44) -> -7157.5253 | J7: =I7/H7 -> -0.03651426 | K7: =20000+(F7*(1-D7)-SUM(Assumptions!B22:B27)*12*1+PMT(Assumptions!B34/12,Assumptions!B35*12,Assumptions!B33)*12-IF((F7*(1-D7)-SUM(Assumptions!B22:B27)*12*1-CashFlow_36m!B45)>0,(F7*(1-D7)-SUM(Assumptions!B22:B27)*12*1-CashFlow_36m!B45)*Assumptions!B44,0))+(G7*(1-D7)-SUM(Assumptions!B22:B27)*12*(1+E7)+PMT(Assumptions!B34/12,Assumptions!B35*12,Assumptions!B33)*12-IF((G7*(1-D7)-SUM(Assumptions!B22:B27)*12*(1+E7)-CashFlow_36m!C45)>0,(G7*(1-D7)-SUM(Assumptions!B22:B27)*12*(1+E7)-CashFlow_36m!C45)*Assumptions!B44,0))+(H7*(1-D7)-SUM(Assumptions!B22:B27)*12*(1+E7)^2+PMT(Assumptions!B34/12,Assumptions!B35*12,Assumptions!B33)*12-IF((H7*(1-D7)-SUM(Assumptions!B22:B27)*12*(1+E7)^2-CashFlow_36m!D45)>0,(H7*(1-D7)-SUM(Assumptions!B22:B27)*12*(1+E7)^2-CashFlow_36m!D45)*Assumptions!B44,0)) -> -42263.715 | L7: =SUM(Assumptions!B22:B27)*12/(Assumptions!B11*(1-D7)) -> 4024.2424
A10: Scenario Risk Metrics
A11: Scenario | B11: Break-even Units | C11: Break-even Sales | D11: Y3 Net Margin | E11: Y3 Closing Cash | F11: Cash Status | G11: Y3 Profit Status | H11: Interpretation
A12: =A5 -> Best | B12: =L5 -> 3405.1282 | C12: =B12*Assumptions!B11 -> 153230.77 | D12: =J5 -> 0.22965125 | E12: =K5 -> 90933.788 | F12: =IF(E12>=0,"Positive","Funding / liquidity gap") -> Positive | G12: =IF(I5>=0,"Profitable","Loss") -> Profitable | H12: Higher demand and lower COGS improve margin, cash generation and resilience.
A13: =A6 -> Base | B13: =L6 -> 3688.8889 | C13: =B13*Assumptions!B11 -> 166000 | D13: =J6 -> 0.13309436 | E13: =K6 -> 31872.875 | F13: =IF(E13>=0,"Positive","Funding / liquidity gap") -> Positive | G13: =IF(I6>=0,"Profitable","Loss") -> Profitable | H13: Base case is the planning reference case and remains dependent on sustained growth and cost control.
A14: =A7 -> Worst | B14: =L7 -> 4024.2424 | C14: =B14*Assumptions!B11 -> 181090.91 | D14: =J7 -> -0.03651426 | E14: =K7 -> -42263.715 | F14: =IF(E14>=0,"Positive","Funding / liquidity gap") -> Funding / liquidity gap | G14: =IF(I7>=0,"Profitable","Loss") -> Loss | H14: Slower growth, higher COGS and higher opex create sustained losses and a material liquidity shortfall.
A17: How to read the scenarios
A18: • Best case: assumes stronger demand growth (35% annually), lower COGS (42%) and tighter opex growth (4%). It tests upside operating leverage rather than claiming a forecast.
A19: • Base case: uses the report-linked 25% growth assumption, 45% COGS and 5% opex growth. Revenue grows from £150,000 to £187,500 and £234,375.
A20: • Worst case: assumes 10% annual growth, 50% COGS and 8% opex growth. The resulting negative closing cash identifies a funding/liquidity risk requiring cost reduction, slower expansion or additional finance.
